INFO | SETTINGS FILE: settings.dev.json

INFO | RUN_ID: 46153

INFO | run_sql_step: steps\step_00_init.sql

CRITICAL | UNCAUGHT EXCEPTION
Traceback (most recent call last):
  File "main.py", line 4, in <module>
    gp.runner.run_steps()
  File "c:\dev\da.main\Job\shared\gp\runner.py", line 617, in run_steps
    run_step(filename)
  File "c:\dev\da.main\Job\shared\gp\runner.py", line 602, in run_step
    if filename.endswith('.sql'):  run_sql_step(filename)
  File "c:\dev\da.main\Job\shared\gp\runner.py", line 368, in run_sql_step
    sql_rendered = str(t.module).replace('$SEMICOLON$',';')
  File "C:\Users\redmond.xia\AppData\Local\Programs\Python\lib\site-packages\jinja2\environment.py", line 1189, in module
    return self._get_default_module()
  File "C:\Users\redmond.xia\AppData\Local\Programs\Python\lib\site-packages\jinja2\environment.py", line 1172, in _get_default_module
    self._module = rv = self.make_module()
  File "C:\Users\redmond.xia\AppData\Local\Programs\Python\lib\site-packages\jinja2\environment.py", line 1155, in make_module
    return TemplateModule(self, self.new_context(vars, shared, locals))
  File "C:\Users\redmond.xia\AppData\Local\Programs\Python\lib\site-packages\jinja2\environment.py", line 1238, in __init__
    body_stream = list(template.root_render_func(context))
  File "<template>", line 20, in root
  File "C:\Users\redmond.xia\AppData\Local\Programs\Python\lib\site-packages\jinja2\runtime.py", line 747, in _fail_with_undefined_error
    raise self._undefined_exception(self._undefined_message)
jinja2.exceptions.UndefinedError: 'None' has no attribute 'database'
INFO | duration seconds: 2.73

INFO | duration minutes: 0.05

INFO | JOB RESULT:  FAIL

WARNING | ARCHIVING AND EMAILING OF LOGS DISABLED

